<?xml version="1.0"?>
<robot xmlns:xacro="http://www.ros.org/wiki/xacro" name="robot_xacro">
<xacro:include filename="$(find exp_assignment2)/urdf/my_robot2.gazebo"/>
					
	<xacro:property name="length_wheel" value="0.04" />
	<xacro:property name="radius_wheel" value="0.1" />

	<xacro:macro name="default_inertial" params="mass">
               <inertial>
                       <mass value="${mass}" />
                       <origin rpy="0 1.5707 1.5707" xyz="0 0 0"/>
                       <inertia ixx="0.000526666666667" ixy="0" ixz="0" iyy="0.000526666666667" iyz="0" izz="0.001"/>
               </inertial>
	</xacro:macro>

    <xacro:macro name="wheel_geometry">
		<geometry>
       			<cylinder length="${length_wheel}" radius="${radius_wheel}"/>
     	</geometry>
	</xacro:macro>
	
	<!--#################  MATERIAL PROPERTIES  ############## -->
  <material name="black">
    <color rgba="0.0 0.0 0.0 1.0"/>
  </material>
  <material name="blue">
    <color rgba="0.203125 0.23828125 0.28515625 1.0"/>
  </material>
  <material name="green">
    <color rgba="0.0 0.8 0.0 1.0"/>
  </material>
  <material name="grey">
    <color rgba="0.2 0.2 0.2 1.0"/>
  </material>
  <material name="orange">
    <color rgba="1.0 0.423529411765 0.0392156862745 1.0"/>
  </material>
  <material name="brown">
    <color rgba="0.870588235294 0.811764705882 0.764705882353 1.0"/>
  </material>
  <material name="red">
    <color rgba="0.80078125 0.12890625 0.1328125 1.0"/>
  </material>
  <material name="white">
    <color rgba="1.0 1.0 1.0 1.0"/>
  </material>


  <!--#################  LINK PROPERTIES  ############## -->
	  <link name="link_chassis">
    <!-- pose and inertial -->
    <pose>0 0 0.1 0 0 0</pose>
    <inertial>
      <mass value="5"/>
      <origin rpy="0 0 0" xyz="0 0 0.1"/>
      <inertia ixx="0.0395416666667" ixy="0" ixz="0" iyy="0.106208333333" iyz="0" izz="0.106208333333"/>
    </inertial>
    <!-- body -->
    <collision name="collision_chassis">
      <geometry>
        <box size="0.5 0.3 0.07"/>
      </geometry>
    </collision>
    <visual>
      <origin rpy="0 0 0" xyz="0 0 0"/>
      <geometry>
        <box size="0.5 0.3 0.07"/>
      </geometry>
      <material name="blue"/>
    </visual>
    <!-- caster front -->
    <collision name="caster_front_collision">
      <origin rpy=" 0 0 0" xyz="0.35 0 -0.05"/>
      <geometry>
        <sphere radius="0.05"/>
      </geometry>
    </collision>
    <visual name="caster_front_visual">
      <origin rpy=" 0 0 0" xyz="0.2 0 -0.05"/>
      <geometry>
        <sphere radius="0.05"/>
      </geometry>
    </visual>
    <!---->
    <!-- caster back for support 
    <collision name="caster_back_collision">
      <origin rpy=" 0 0 0" xyz="-0.35 0 -0.05"/>
      <geometry>
        <sphere radius="0.05"/>
      </geometry>
    </collision>
    <visual name="caster_back_visual">
      <origin rpy=" 0 0 0" xyz="-0.35 0 -0.05"/>
      <geometry>
        <sphere radius="0.05"/>
      </geometry>
    </visual>-->
  </link>

  <link name="link_back_right_wheel">
    <xacro:default_inertial mass="0.2"/>
    <collision name="link_back_right_wheel_collision">
      <origin rpy="0 1.5707 1.5707" xyz="0 0 0"/>
      <xacro:wheel_geometry />
    </collision>
    <visual name="link_back_right_wheel_visual">
      <origin rpy="0 1.5707 1.5707" xyz="0 0 0"/>
      <xacro:wheel_geometry />
      <material name="red"/>
    </visual>
  </link>

   <link name="link_back_left_wheel">
    <xacro:default_inertial mass="0.2"/>
    <collision name="link_back_left_wheel_collision">
      <origin rpy="0 1.5707 1.5707" xyz="0 0 0"/>
      <xacro:wheel_geometry />
    </collision>
    <visual name="link_back_left_wheel_visual">
      <origin rpy="0 1.5707 1.5707" xyz="0 0 0"/>
      <xacro:wheel_geometry />
      <material name="red"/>
    </visual>
  </link>
 <!--
   <link name="link_front_right_wheel">
    <xacro:default_inertial mass="0.2"/>
    <collision name="link_front_right_wheel_collision">
      <origin rpy="0 1.5707 1.5707" xyz="0 0 0"/>
      <xacro:wheel_geometry />
    </collision>
    <visual name="link_front_right_wheel_visual">
      <origin rpy="0 1.5707 1.5707" xyz="0 0 0"/>
      <xacro:wheel_geometry />
      <material name="red"/>
    </visual>
  </link>
   <link name="link_front_left_wheel">
    <xacro:default_inertial mass="0.2"/>
    <collision name="link_front_left_wheel_collision">
      <origin rpy="0 1.5707 1.5707" xyz="0 0 0"/>
      <xacro:wheel_geometry />
    </collision>
    <visual name="link_front_left_wheel_visual">
      <origin rpy="0 1.5707 1.5707" xyz="0 0 0"/>
      <xacro:wheel_geometry />
      <material name="red"/>
    </visual>
  </link>
-->
  <!--###############################################
                Joint definitions
  ####################################################-->
  <joint name="joint_back_right_wheel" type="continuous">
    <origin rpy="0 0 0" xyz="-0.05 0.15 0"/>
    <child link="link_back_right_wheel"/>
    <parent link="link_chassis"/>
    <axis rpy="0 0 0" xyz="0 1 0"/>
    <limit effort="10000" velocity="1000"/>
    <joint_properties damping="1.0" friction="1.0"/>
  </joint>
  
  
  <joint name="joint_back_left_wheel" type="continuous">
    <origin rpy="0 0 0" xyz="-0.05 -0.15 0"/>
    <child link="link_back_left_wheel"/>
    <parent link="link_chassis"/>
    <axis rpy="0 0 0" xyz="0 1 0"/>
    <limit effort="10000" velocity="1000"/>
    <joint_properties damping="1.0" friction="1.0"/>
  </joint>
<!--
  <joint name="joint_front_right_wheel" type="continuous">
    <origin rpy="0 0 0" xyz="0.20 0.15 0"/>
    <child link="link_front_right_wheel"/>
    <parent link="link_chassis"/>
    <axis rpy="0 0 0" xyz="0 1 0"/>
    <limit effort="10000" velocity="1000"/>
    <joint_properties damping="1.0" friction="1.0"/>
  </joint>
  
  
  <joint name="joint_front_left_wheel" type="continuous">
    <origin rpy="0 0 0" xyz="0.20 -0.15 0"/>
    <child link="link_front_left_wheel"/>
    <parent link="link_chassis"/>
    <axis rpy="0 0 0" xyz="0 1 0"/>
    <limit effort="10000" velocity="1000"/>
    <joint_properties damping="1.0" friction="1.0"/>
  </joint>
-->
<!--camera links - neck definition -->

  <link name="neck_base_link">
  	<inertial>
  		<mass value="0.001"/>
  		<origin xyz="0 0 0" rpy="0 0 0" />
  		<inertia ixx="0.0000416666667" ixy="0" ixz="0" iyy="0.0000416666667" iyz="0" izz="0.0000416666667"/>
  	</inertial>
  	<collision>
  	  <origin xyz="0 0 0" rpy="0 0 0"/>
      <geometry>
        <box size="0.1 0.1 0.1"/>
      </geometry>
  	</collision>
  	<visual>
  	  <origin xyz="0 0 0" rpy="0 0 0"/>
      <geometry>
        <box size="0.1 0.1 0.1"/>
      </geometry>
      <material name="red" />
  	</visual>
  </link>

  <joint name="neck_base_to_chassis" type="fixed">
  	<origin rpy="0 0 0" xyz="0.10 0 0.085"/>
  	<parent link="link_chassis"/>
  	<child link="neck_base_link"/>
  </joint>


  <link name="neck_link">
  	<inertial>
  		<mass value="0.00125"/>
  		<origin xyz="0 0 0" rpy="0 0 0" />
  		<inertia ixx="0.000010279" ixy="0" ixz="0" iyy="0.000010279" iyz="0" izz="0.000007225"/>
  	</inertial>
  	<collision>
  	  <origin xyz="0 0 0.125" rpy="0 0 0"/>
      <geometry>
        <cylinder radius="0.04" length="0.25"/>
      </geometry>
  	</collision>
  	<visual>
  	  <origin xyz="0 0 0.125" rpy="0 0 0"/>
      <geometry>
        <cylinder radius="0.04" length="0.25"/>
      </geometry>
      <material name="red" />
  	</visual>
  </link>
  <joint name="neck_joint" type="revolute">
  	<axis xyz="0 0 1"/>
  	<limit effort="1000.0" lower="-6.28" upper="6.28" velocity="0.2"/>
  	<origin rpy="0 0 0" xyz="0 0 0.05"/>
  	<parent link="neck_base_link"/>
  	<child link="neck_link"/>
  </joint>


  <link name="camera_link">
  	<inertial>
  		<mass value="0.001"/>
  		<origin xyz="0 0 0" rpy="0 0 0" />
  		<inertia ixx="0.00000416666667" ixy="0" ixz="0" iyy="0.00000416666667" iyz="0" izz="0.00000416666667"/>
  	</inertial>
  	<collision>
  	  <origin xyz="0.05 0 0.025" rpy="0 0 0"/>
      <geometry>
        <box size="0.15 0.15 0.05"/>
      </geometry>
  	</collision>
  	<visual>
  	  <origin xyz="0.05 0 0.025" rpy="0 0 0"/>
      <geometry>
        <box size="0.05 0.15 0.05"/>
      </geometry>
      <material name="white" />
  	</visual>
  </link>

  <joint name="camera_joint" type="fixed">
  	<origin rpy="0 0 0" xyz="0 0 0.25"/>
  	<parent link="neck_link"/>
  	<child link="camera_link"/>
  </joint>

<transmission name="neck_joint_trans">
	<type>transmission_interface/SimpleTransmission</type>
	<joint name="neck_joint">
		<hardwareInterface>hardware_interface/EffortJointInterface</hardwareInterface>
	</joint>
	<actuator name="motor1">
		<hardwareInterface>hardware_interface/EffortJointInterface</hardwareInterface>
		<mechanicalInterface>1</mechanicalInterface>
	</actuator>
</transmission>





</robot>